Watching for file changes with StatReloader
C:\Users\SUBRAMANI\AppData\Roaming\Python\Python313\site-packages\PIL\TiffTags.py changed, reloading.
Watching for file changes with StatReloader
Watching for file changes with StatReloader
Watching for file changes with StatReloader
Not Found: /
"GET / HTTP/1.1" 404 2773
Not Found: /favicon.ico
"GET /favicon.ico HTTP/1.1" 404 2824
C:\Users\SUBRAMANI\dine\Ecoshift\backend\ecoswitch_backend\settings.py changed, reloading.
Watching for file changes with StatReloader
C:\Users\SUBRAMANI\dine\Ecoshift\backend\ecoswitch_backend\settings.py changed, reloading.
Watching for file changes with StatReloader
"OPTIONS /api/auth/register/ HTTP/1.1" 200 0
Internal Server Error: /api/auth/register/
Traceback (most recent call last):
  File "C:\Users\SUBRAMANI\AppData\Roaming\Python\Python313\site-packages\django\db\backends\utils.py", line 89, in _execute
    return self.cursor.execute(sql, params)
           ~~~~~~~~~~~~~~~~~~~^^^^^^^^^^^^^
  File "C:\Users\SUBRAMANI\AppData\Roaming\Python\Python313\site-packages\django\db\backends\sqlite3\base.py", line 328, in execute
    return super().execute(query, params)
           ~~~~~~~~~~~~~~~^^^^^^^^^^^^^^^
sqlite3.OperationalError: no such table: auth_user

The above exception was the direct cause of the following exception:

Traceback (most recent call last):
  File "C:\Users\SUBRAMANI\AppData\Roaming\Python\Python313\site-packages\django\core\handlers\exception.py", line 55, in inner
    response = get_response(request)
  File "C:\Users\SUBRAMANI\AppData\Roaming\Python\Python313\site-packages\django\core\handlers\base.py", line 197, in _get_response
    response = wrapped_callback(request, *callback_args, **callback_kwargs)
  File "C:\Users\SUBRAMANI\AppData\Roaming\Python\Python313\site-packages\django\views\decorators\csrf.py", line 56, in wrapper_view
    return view_func(*args, **kwargs)
  File "C:\Users\SUBRAMANI\AppData\Roaming\Python\Python313\site-packages\django\views\generic\base.py", line 104, in view
    return self.dispatch(request, *args, **kwargs)
           ~~~~~~~~~~~~~^^^^^^^^^^^^^^^^^^^^^^^^^^
  File "C:\Users\SUBRAMANI\AppData\Roaming\Python\Python313\site-packages\rest_framework\views.py", line 509, in dispatch
    response = self.handle_exception(exc)
  File "C:\Users\SUBRAMANI\AppData\Roaming\Python\Python313\site-packages\rest_framework\views.py", line 469, in handle_exception
    self.raise_uncaught_exception(exc)
    ~~~~~~~~~~~~~~~~~~~~~~~~~~~~~^^^^^
  File "C:\Users\SUBRAMANI\AppData\Roaming\Python\Python313\site-packages\rest_framework\views.py", line 480, in raise_uncaught_exception
    raise exc
  File "C:\Users\SUBRAMANI\AppData\Roaming\Python\Python313\site-packages\rest_framework\views.py", line 506, in dispatch
    response = handler(request, *args, **kwargs)
  File "C:\Users\SUBRAMANI\AppData\Roaming\Python\Python313\site-packages\rest_framework\decorators.py", line 50, in handler
    return func(*args, **kwargs)
  File "C:\Users\SUBRAMANI\dine\Ecoshift\backend\authentication\views.py", line 55, in register_user
    if serializer.is_valid():
       ~~~~~~~~~~~~~~~~~~~^^
  File "C:\Users\SUBRAMANI\AppData\Roaming\Python\Python313\site-packages\rest_framework\serializers.py", line 227, in is_valid
    self._validated_data = self.run_validation(self.initial_data)
                           ~~~~~~~~~~~~~~~~~~~^^^^^^^^^^^^^^^^^^^
  File "C:\Users\SUBRAMANI\AppData\Roaming\Python\Python313\site-packages\rest_framework\serializers.py", line 426, in run_validation
    value = self.to_internal_value(data)
  File "C:\Users\SUBRAMANI\AppData\Roaming\Python\Python313\site-packages\rest_framework\serializers.py", line 483, in to_internal_value
    validated_value = field.run_validation(primitive_value)
  File "C:\Users\SUBRAMANI\AppData\Roaming\Python\Python313\site-packages\rest_framework\fields.py", line 751, in run_validation
    return super().run_validation(data)
           ~~~~~~~~~~~~~~~~~~~~~~^^^^^^
  File "C:\Users\SUBRAMANI\AppData\Roaming\Python\Python313\site-packages\rest_framework\fields.py", line 548, in run_validation
    self.run_validators(value)
    ~~~~~~~~~~~~~~~~~~~^^^^^^^
  File "C:\Users\SUBRAMANI\AppData\Roaming\Python\Python313\site-packages\rest_framework\fields.py", line 560, in run_validators
    validator(value, self)
    ~~~~~~~~~^^^^^^^^^^^^^
  File "C:\Users\SUBRAMANI\AppData\Roaming\Python\Python313\site-packages\rest_framework\validators.py", line 73, in __call__
    if qs_exists(queryset):
       ~~~~~~~~~^^^^^^^^^^
  File "C:\Users\SUBRAMANI\AppData\Roaming\Python\Python313\site-packages\rest_framework\validators.py", line 21, in qs_exists
    return queryset.exists()
           ~~~~~~~~~~~~~~~^^
  File "C:\Users\SUBRAMANI\AppData\Roaming\Python\Python313\site-packages\django\db\models\query.py", line 1241, in exists
    return self.query.has_results(using=self.db)
           ~~~~~~~~~~~~~~~~~~~~~~^^^^^^^^^^^^^^^
  File "C:\Users\SUBRAMANI\AppData\Roaming\Python\Python313\site-packages\django\db\models\sql\query.py", line 598, in has_results
    return compiler.has_results()
           ~~~~~~~~~~~~~~~~~~~~^^
  File "C:\Users\SUBRAMANI\AppData\Roaming\Python\Python313\site-packages\django\db\models\sql\compiler.py", line 1530, in has_results
    return bool(self.execute_sql(SINGLE))
                ~~~~~~~~~~~~~~~~^^^^^^^^
  File "C:\Users\SUBRAMANI\AppData\Roaming\Python\Python313\site-packages\django\db\models\sql\compiler.py", line 1562, in execute_sql
    cursor.execute(sql, params)
    ~~~~~~~~~~~~~~^^^^^^^^^^^^^
  File "C:\Users\SUBRAMANI\AppData\Roaming\Python\Python313\site-packages\django\db\backends\utils.py", line 102, in execute
    return super().execute(sql, params)
           ~~~~~~~~~~~~~~~^^^^^^^^^^^^^
  File "C:\Users\SUBRAMANI\AppData\Roaming\Python\Python313\site-packages\django\db\backends\utils.py", line 67, in execute
    return self._execute_with_wrappers(
           ~~~~~~~~~~~~~~~~~~~~~~~~~~~^
        sql, params, many=False, executor=self._execute
        ^^^^^^^^^^^^^^^^^^^^^^^^^^^^^^^^^^^^^^^^^^^^^^^
    )
    ^
  File "C:\Users\SUBRAMANI\AppData\Roaming\Python\Python313\site-packages\django\db\backends\utils.py", line 80, in _execute_with_wrappers
    return executor(sql, params, many, context)
  File "C:\Users\SUBRAMANI\AppData\Roaming\Python\Python313\site-packages\django\db\backends\utils.py", line 84, in _execute
    with self.db.wrap_database_errors:
         ^^^^^^^^^^^^^^^^^^^^^^^^^^^^
  File "C:\Users\SUBRAMANI\AppData\Roaming\Python\Python313\site-packages\django\db\utils.py", line 91, in __exit__
    raise dj_exc_value.with_traceback(traceback) from exc_value
  File "C:\Users\SUBRAMANI\AppData\Roaming\Python\Python313\site-packages\django\db\backends\utils.py", line 89, in _execute
    return self.cursor.execute(sql, params)
           ~~~~~~~~~~~~~~~~~~~^^^^^^^^^^^^^
  File "C:\Users\SUBRAMANI\AppData\Roaming\Python\Python313\site-packages\django\db\backends\sqlite3\base.py", line 328, in execute
    return super().execute(query, params)
           ~~~~~~~~~~~~~~~^^^^^^^^^^^^^^^
django.db.utils.OperationalError: no such table: auth_user
"POST /api/auth/register/ HTTP/1.1" 500 201193
Internal Server Error: /api/auth/register/
Traceback (most recent call last):
  File "C:\Users\SUBRAMANI\AppData\Roaming\Python\Python313\site-packages\django\db\backends\utils.py", line 89, in _execute
    return self.cursor.execute(sql, params)
           ~~~~~~~~~~~~~~~~~~~^^^^^^^^^^^^^
  File "C:\Users\SUBRAMANI\AppData\Roaming\Python\Python313\site-packages\django\db\backends\sqlite3\base.py", line 328, in execute
    return super().execute(query, params)
           ~~~~~~~~~~~~~~~^^^^^^^^^^^^^^^
sqlite3.OperationalError: no such table: auth_user

The above exception was the direct cause of the following exception:

Traceback (most recent call last):
  File "C:\Users\SUBRAMANI\AppData\Roaming\Python\Python313\site-packages\django\core\handlers\exception.py", line 55, in inner
    response = get_response(request)
  File "C:\Users\SUBRAMANI\AppData\Roaming\Python\Python313\site-packages\django\core\handlers\base.py", line 197, in _get_response
    response = wrapped_callback(request, *callback_args, **callback_kwargs)
  File "C:\Users\SUBRAMANI\AppData\Roaming\Python\Python313\site-packages\django\views\decorators\csrf.py", line 56, in wrapper_view
    return view_func(*args, **kwargs)
  File "C:\Users\SUBRAMANI\AppData\Roaming\Python\Python313\site-packages\django\views\generic\base.py", line 104, in view
    return self.dispatch(request, *args, **kwargs)
           ~~~~~~~~~~~~~^^^^^^^^^^^^^^^^^^^^^^^^^^
  File "C:\Users\SUBRAMANI\AppData\Roaming\Python\Python313\site-packages\rest_framework\views.py", line 509, in dispatch
    response = self.handle_exception(exc)
  File "C:\Users\SUBRAMANI\AppData\Roaming\Python\Python313\site-packages\rest_framework\views.py", line 469, in handle_exception
    self.raise_uncaught_exception(exc)
    ~~~~~~~~~~~~~~~~~~~~~~~~~~~~~^^^^^
  File "C:\Users\SUBRAMANI\AppData\Roaming\Python\Python313\site-packages\rest_framework\views.py", line 480, in raise_uncaught_exception
    raise exc
  File "C:\Users\SUBRAMANI\AppData\Roaming\Python\Python313\site-packages\rest_framework\views.py", line 506, in dispatch
    response = handler(request, *args, **kwargs)
  File "C:\Users\SUBRAMANI\AppData\Roaming\Python\Python313\site-packages\rest_framework\decorators.py", line 50, in handler
    return func(*args, **kwargs)
  File "C:\Users\SUBRAMANI\dine\Ecoshift\backend\authentication\views.py", line 55, in register_user
    if serializer.is_valid():
       ~~~~~~~~~~~~~~~~~~~^^
  File "C:\Users\SUBRAMANI\AppData\Roaming\Python\Python313\site-packages\rest_framework\serializers.py", line 227, in is_valid
    self._validated_data = self.run_validation(self.initial_data)
                           ~~~~~~~~~~~~~~~~~~~^^^^^^^^^^^^^^^^^^^
  File "C:\Users\SUBRAMANI\AppData\Roaming\Python\Python313\site-packages\rest_framework\serializers.py", line 426, in run_validation
    value = self.to_internal_value(data)
  File "C:\Users\SUBRAMANI\AppData\Roaming\Python\Python313\site-packages\rest_framework\serializers.py", line 483, in to_internal_value
    validated_value = field.run_validation(primitive_value)
  File "C:\Users\SUBRAMANI\AppData\Roaming\Python\Python313\site-packages\rest_framework\fields.py", line 751, in run_validation
    return super().run_validation(data)
           ~~~~~~~~~~~~~~~~~~~~~~^^^^^^
  File "C:\Users\SUBRAMANI\AppData\Roaming\Python\Python313\site-packages\rest_framework\fields.py", line 548, in run_validation
    self.run_validators(value)
    ~~~~~~~~~~~~~~~~~~~^^^^^^^
  File "C:\Users\SUBRAMANI\AppData\Roaming\Python\Python313\site-packages\rest_framework\fields.py", line 560, in run_validators
    validator(value, self)
    ~~~~~~~~~^^^^^^^^^^^^^
  File "C:\Users\SUBRAMANI\AppData\Roaming\Python\Python313\site-packages\rest_framework\validators.py", line 73, in __call__
    if qs_exists(queryset):
       ~~~~~~~~~^^^^^^^^^^
  File "C:\Users\SUBRAMANI\AppData\Roaming\Python\Python313\site-packages\rest_framework\validators.py", line 21, in qs_exists
    return queryset.exists()
           ~~~~~~~~~~~~~~~^^
  File "C:\Users\SUBRAMANI\AppData\Roaming\Python\Python313\site-packages\django\db\models\query.py", line 1241, in exists
    return self.query.has_results(using=self.db)
           ~~~~~~~~~~~~~~~~~~~~~~^^^^^^^^^^^^^^^
  File "C:\Users\SUBRAMANI\AppData\Roaming\Python\Python313\site-packages\django\db\models\sql\query.py", line 598, in has_results
    return compiler.has_results()
           ~~~~~~~~~~~~~~~~~~~~^^
  File "C:\Users\SUBRAMANI\AppData\Roaming\Python\Python313\site-packages\django\db\models\sql\compiler.py", line 1530, in has_results
    return bool(self.execute_sql(SINGLE))
                ~~~~~~~~~~~~~~~~^^^^^^^^
  File "C:\Users\SUBRAMANI\AppData\Roaming\Python\Python313\site-packages\django\db\models\sql\compiler.py", line 1562, in execute_sql
    cursor.execute(sql, params)
    ~~~~~~~~~~~~~~^^^^^^^^^^^^^
  File "C:\Users\SUBRAMANI\AppData\Roaming\Python\Python313\site-packages\django\db\backends\utils.py", line 102, in execute
    return super().execute(sql, params)
           ~~~~~~~~~~~~~~~^^^^^^^^^^^^^
  File "C:\Users\SUBRAMANI\AppData\Roaming\Python\Python313\site-packages\django\db\backends\utils.py", line 67, in execute
    return self._execute_with_wrappers(
           ~~~~~~~~~~~~~~~~~~~~~~~~~~~^
        sql, params, many=False, executor=self._execute
        ^^^^^^^^^^^^^^^^^^^^^^^^^^^^^^^^^^^^^^^^^^^^^^^
    )
    ^
  File "C:\Users\SUBRAMANI\AppData\Roaming\Python\Python313\site-packages\django\db\backends\utils.py", line 80, in _execute_with_wrappers
    return executor(sql, params, many, context)
  File "C:\Users\SUBRAMANI\AppData\Roaming\Python\Python313\site-packages\django\db\backends\utils.py", line 84, in _execute
    with self.db.wrap_database_errors:
         ^^^^^^^^^^^^^^^^^^^^^^^^^^^^
  File "C:\Users\SUBRAMANI\AppData\Roaming\Python\Python313\site-packages\django\db\utils.py", line 91, in __exit__
    raise dj_exc_value.with_traceback(traceback) from exc_value
  File "C:\Users\SUBRAMANI\AppData\Roaming\Python\Python313\site-packages\django\db\backends\utils.py", line 89, in _execute
    return self.cursor.execute(sql, params)
           ~~~~~~~~~~~~~~~~~~~^^^^^^^^^^^^^
  File "C:\Users\SUBRAMANI\AppData\Roaming\Python\Python313\site-packages\django\db\backends\sqlite3\base.py", line 328, in execute
    return super().execute(query, params)
           ~~~~~~~~~~~~~~~^^^^^^^^^^^^^^^
django.db.utils.OperationalError: no such table: auth_user
"POST /api/auth/register/ HTTP/1.1" 500 201085
"OPTIONS /api/auth/login/ HTTP/1.1" 200 0
Internal Server Error: /api/auth/login/
Traceback (most recent call last):
  File "C:\Users\SUBRAMANI\AppData\Roaming\Python\Python313\site-packages\django\db\backends\utils.py", line 89, in _execute
    return self.cursor.execute(sql, params)
           ~~~~~~~~~~~~~~~~~~~^^^^^^^^^^^^^
  File "C:\Users\SUBRAMANI\AppData\Roaming\Python\Python313\site-packages\django\db\backends\sqlite3\base.py", line 328, in execute
    return super().execute(query, params)
           ~~~~~~~~~~~~~~~^^^^^^^^^^^^^^^
sqlite3.OperationalError: no such table: auth_user

The above exception was the direct cause of the following exception:

Traceback (most recent call last):
  File "C:\Users\SUBRAMANI\AppData\Roaming\Python\Python313\site-packages\django\core\handlers\exception.py", line 55, in inner
    response = get_response(request)
  File "C:\Users\SUBRAMANI\AppData\Roaming\Python\Python313\site-packages\django\core\handlers\base.py", line 197, in _get_response
    response = wrapped_callback(request, *callback_args, **callback_kwargs)
  File "C:\Users\SUBRAMANI\AppData\Roaming\Python\Python313\site-packages\django\views\decorators\csrf.py", line 56, in wrapper_view
    return view_func(*args, **kwargs)
  File "C:\Users\SUBRAMANI\AppData\Roaming\Python\Python313\site-packages\django\views\generic\base.py", line 104, in view
    return self.dispatch(request, *args, **kwargs)
           ~~~~~~~~~~~~~^^^^^^^^^^^^^^^^^^^^^^^^^^
  File "C:\Users\SUBRAMANI\AppData\Roaming\Python\Python313\site-packages\rest_framework\views.py", line 509, in dispatch
    response = self.handle_exception(exc)
  File "C:\Users\SUBRAMANI\AppData\Roaming\Python\Python313\site-packages\rest_framework\views.py", line 469, in handle_exception
    self.raise_uncaught_exception(exc)
    ~~~~~~~~~~~~~~~~~~~~~~~~~~~~~^^^^^
  File "C:\Users\SUBRAMANI\AppData\Roaming\Python\Python313\site-packages\rest_framework\views.py", line 480, in raise_uncaught_exception
    raise exc
  File "C:\Users\SUBRAMANI\AppData\Roaming\Python\Python313\site-packages\rest_framework\views.py", line 506, in dispatch
    response = handler(request, *args, **kwargs)
  File "C:\Users\SUBRAMANI\dine\Ecoshift\backend\authentication\views.py", line 29, in post
    if serializer.is_valid():
       ~~~~~~~~~~~~~~~~~~~^^
  File "C:\Users\SUBRAMANI\AppData\Roaming\Python\Python313\site-packages\rest_framework\serializers.py", line 227, in is_valid
    self._validated_data = self.run_validation(self.initial_data)
                           ~~~~~~~~~~~~~~~~~~~^^^^^^^^^^^^^^^^^^^
  File "C:\Users\SUBRAMANI\AppData\Roaming\Python\Python313\site-packages\rest_framework\serializers.py", line 429, in run_validation
    value = self.validate(value)
  File "C:\Users\SUBRAMANI\dine\Ecoshift\backend\authentication\serializers.py", line 43, in validate
    user = authenticate(username=email, password=password)
  File "C:\Users\SUBRAMANI\AppData\Roaming\Python\Python313\site-packages\django\views\decorators\debug.py", line 42, in sensitive_variables_wrapper
    return func(*func_args, **func_kwargs)
  File "C:\Users\SUBRAMANI\AppData\Roaming\Python\Python313\site-packages\django\contrib\auth\__init__.py", line 77, in authenticate
    user = backend.authenticate(request, **credentials)
  File "C:\Users\SUBRAMANI\AppData\Roaming\Python\Python313\site-packages\django\contrib\auth\backends.py", line 46, in authenticate
    user = UserModel._default_manager.get_by_natural_key(username)
  File "C:\Users\SUBRAMANI\AppData\Roaming\Python\Python313\site-packages\django\contrib\auth\base_user.py", line 54, in get_by_natural_key
    return self.get(**{self.model.USERNAME_FIELD: username})
           ~~~~~~~~^^^^^^^^^^^^^^^^^^^^^^^^^^^^^^^^^^^^^^^^^
  File "C:\Users\SUBRAMANI\AppData\Roaming\Python\Python313\site-packages\django\db\models\manager.py", line 87, in manager_method
    return getattr(self.get_queryset(), name)(*args, **kwargs)
           ~~~~~~~~~~~~~~~~~~~~~~~~~~~~~~~~~~^^^^^^^^^^^^^^^^^
  File "C:\Users\SUBRAMANI\AppData\Roaming\Python\Python313\site-packages\django\db\models\query.py", line 633, in get
    num = len(clone)
  File "C:\Users\SUBRAMANI\AppData\Roaming\Python\Python313\site-packages\django\db\models\query.py", line 380, in __len__
    self._fetch_all()
    ~~~~~~~~~~~~~~~^^
  File "C:\Users\SUBRAMANI\AppData\Roaming\Python\Python313\site-packages\django\db\models\query.py", line 1881, in _fetch_all
    self._result_cache = list(self._iterable_class(self))
                         ~~~~^^^^^^^^^^^^^^^^^^^^^^^^^^^^
  File "C:\Users\SUBRAMANI\AppData\Roaming\Python\Python313\site-packages\django\db\models\query.py", line 91, in __iter__
    results = compiler.execute_sql(
        chunked_fetch=self.chunked_fetch, chunk_size=self.chunk_size
    )
  File "C:\Users\SUBRAMANI\AppData\Roaming\Python\Python313\site-packages\django\db\models\sql\compiler.py", line 1562, in execute_sql
    cursor.execute(sql, params)
    ~~~~~~~~~~~~~~^^^^^^^^^^^^^
  File "C:\Users\SUBRAMANI\AppData\Roaming\Python\Python313\site-packages\django\db\backends\utils.py", line 102, in execute
    return super().execute(sql, params)
           ~~~~~~~~~~~~~~~^^^^^^^^^^^^^
  File "C:\Users\SUBRAMANI\AppData\Roaming\Python\Python313\site-packages\django\db\backends\utils.py", line 67, in execute
    return self._execute_with_wrappers(
           ~~~~~~~~~~~~~~~~~~~~~~~~~~~^
        sql, params, many=False, executor=self._execute
        ^^^^^^^^^^^^^^^^^^^^^^^^^^^^^^^^^^^^^^^^^^^^^^^
    )
    ^
  File "C:\Users\SUBRAMANI\AppData\Roaming\Python\Python313\site-packages\django\db\backends\utils.py", line 80, in _execute_with_wrappers
    return executor(sql, params, many, context)
  File "C:\Users\SUBRAMANI\AppData\Roaming\Python\Python313\site-packages\django\db\backends\utils.py", line 84, in _execute
    with self.db.wrap_database_errors:
         ^^^^^^^^^^^^^^^^^^^^^^^^^^^^
  File "C:\Users\SUBRAMANI\AppData\Roaming\Python\Python313\site-packages\django\db\utils.py", line 91, in __exit__
    raise dj_exc_value.with_traceback(traceback) from exc_value
  File "C:\Users\SUBRAMANI\AppData\Roaming\Python\Python313\site-packages\django\db\backends\utils.py", line 89, in _execute
    return self.cursor.execute(sql, params)
           ~~~~~~~~~~~~~~~~~~~^^^^^^^^^^^^^
  File "C:\Users\SUBRAMANI\AppData\Roaming\Python\Python313\site-packages\django\db\backends\sqlite3\base.py", line 328, in execute
    return super().execute(query, params)
           ~~~~~~~~~~~~~~~^^^^^^^^^^^^^^^
django.db.utils.OperationalError: no such table: auth_user
"POST /api/auth/login/ HTTP/1.1" 500 203349
Not Found: /
"GET / HTTP/1.1" 404 2773
C:\Users\SUBRAMANI\dine\Ecoshift\backend\merchants\apps.py changed, reloading.
Watching for file changes with StatReloader
C:\Users\SUBRAMANI\dine\Ecoshift\backend\ecoswitch_backend\urls.py changed, reloading.
Watching for file changes with StatReloader
C:\Users\SUBRAMANI\dine\Ecoshift\backend\customers\models.py changed, reloading.
Watching for file changes with StatReloader
C:\Users\SUBRAMANI\dine\Ecoshift\backend\ecoswitch_backend\urls.py changed, reloading.
Watching for file changes with StatReloader
C:\Users\SUBRAMANI\dine\Ecoshift\backend\authentication\serializers.py changed, reloading.
Watching for file changes with StatReloader
Watching for file changes with StatReloader
Watching for file changes with StatReloader
Not Found: /
"GET / HTTP/1.1" 404 2773
Not Found: /favicon.ico
"GET /favicon.ico HTTP/1.1" 404 2824
"GET /admin HTTP/1.1" 301 0
"GET /admin/ HTTP/1.1" 302 0
"GET /admin/login/?next=/admin/ HTTP/1.1" 200 4178
"GET /static/admin/css/base.css HTTP/1.1" 200 21207
"GET /static/admin/css/login.css HTTP/1.1" 200 958
"GET /static/admin/css/responsive.css HTTP/1.1" 200 18533
"GET /static/admin/css/nav_sidebar.css HTTP/1.1" 200 2694
"GET /static/admin/js/nav_sidebar.js HTTP/1.1" 200 3063
"GET /static/admin/css/dark_mode.css HTTP/1.1" 200 2929
"GET /static/admin/js/theme.js HTTP/1.1" 200 1943
Internal Server Error: /admin/login/
Traceback (most recent call last):
  File "C:\Users\SUBRAMANI\AppData\Roaming\Python\Python313\site-packages\django\db\backends\utils.py", line 89, in _execute
    return self.cursor.execute(sql, params)
           ~~~~~~~~~~~~~~~~~~~^^^^^^^^^^^^^
  File "C:\Users\SUBRAMANI\AppData\Roaming\Python\Python313\site-packages\django\db\backends\sqlite3\base.py", line 328, in execute
    return super().execute(query, params)
           ~~~~~~~~~~~~~~~^^^^^^^^^^^^^^^
sqlite3.OperationalError: no such table: auth_user

The above exception was the direct cause of the following exception:

Traceback (most recent call last):
  File "C:\Users\SUBRAMANI\AppData\Roaming\Python\Python313\site-packages\django\core\handlers\exception.py", line 55, in inner
    response = get_response(request)
  File "C:\Users\SUBRAMANI\AppData\Roaming\Python\Python313\site-packages\django\core\handlers\base.py", line 197, in _get_response
    response = wrapped_callback(request, *callback_args, **callback_kwargs)
  File "C:\Users\SUBRAMANI\AppData\Roaming\Python\Python313\site-packages\django\utils\decorators.py", line 46, in _wrapper
    return bound_method(*args, **kwargs)
  File "C:\Users\SUBRAMANI\AppData\Roaming\Python\Python313\site-packages\django\views\decorators\cache.py", line 62, in _wrapper_view_func
    response = view_func(request, *args, **kwargs)
  File "C:\Users\SUBRAMANI\AppData\Roaming\Python\Python313\site-packages\django\contrib\admin\sites.py", line 441, in login
    return LoginView.as_view(**defaults)(request)
           ~~~~~~~~~~~~~~~~~~~~~~~~~~~~~^^^^^^^^^
  File "C:\Users\SUBRAMANI\AppData\Roaming\Python\Python313\site-packages\django\views\generic\base.py", line 104, in view
    return self.dispatch(request, *args, **kwargs)
           ~~~~~~~~~~~~~^^^^^^^^^^^^^^^^^^^^^^^^^^
  File "C:\Users\SUBRAMANI\AppData\Roaming\Python\Python313\site-packages\django\utils\decorators.py", line 46, in _wrapper
    return bound_method(*args, **kwargs)
  File "C:\Users\SUBRAMANI\AppData\Roaming\Python\Python313\site-packages\django\views\decorators\debug.py", line 92, in sensitive_post_parameters_wrapper
    return view(request, *args, **kwargs)
  File "C:\Users\SUBRAMANI\AppData\Roaming\Python\Python313\site-packages\django\utils\decorators.py", line 46, in _wrapper
    return bound_method(*args, **kwargs)
  File "C:\Users\SUBRAMANI\AppData\Roaming\Python\Python313\site-packages\django\utils\decorators.py", line 134, in _wrapper_view
    response = view_func(request, *args, **kwargs)
  File "C:\Users\SUBRAMANI\AppData\Roaming\Python\Python313\site-packages\django\utils\decorators.py", line 46, in _wrapper
    return bound_method(*args, **kwargs)
  File "C:\Users\SUBRAMANI\AppData\Roaming\Python\Python313\site-packages\django\views\decorators\cache.py", line 62, in _wrapper_view_func
    response = view_func(request, *args, **kwargs)
  File "C:\Users\SUBRAMANI\AppData\Roaming\Python\Python313\site-packages\django\contrib\auth\views.py", line 90, in dispatch
    return super().dispatch(request, *args, **kwargs)
           ~~~~~~~~~~~~~~~~^^^^^^^^^^^^^^^^^^^^^^^^^^
  File "C:\Users\SUBRAMANI\AppData\Roaming\Python\Python313\site-packages\django\views\generic\base.py", line 143, in dispatch
    return handler(request, *args, **kwargs)
  File "C:\Users\SUBRAMANI\AppData\Roaming\Python\Python313\site-packages\django\views\generic\edit.py", line 152, in post
    if form.is_valid():
       ~~~~~~~~~~~~~^^
  File "C:\Users\SUBRAMANI\AppData\Roaming\Python\Python313\site-packages\django\forms\forms.py", line 201, in is_valid
    return self.is_bound and not self.errors
                                 ^^^^^^^^^^^
  File "C:\Users\SUBRAMANI\AppData\Roaming\Python\Python313\site-packages\django\forms\forms.py", line 196, in errors
    self.full_clean()
    ~~~~~~~~~~~~~~~^^
  File "C:\Users\SUBRAMANI\AppData\Roaming\Python\Python313\site-packages\django\forms\forms.py", line 434, in full_clean
    self._clean_form()
    ~~~~~~~~~~~~~~~~^^
  File "C:\Users\SUBRAMANI\AppData\Roaming\Python\Python313\site-packages\django\forms\forms.py", line 455, in _clean_form
    cleaned_data = self.clean()
  File "C:\Users\SUBRAMANI\AppData\Roaming\Python\Python313\site-packages\django\contrib\auth\forms.py", line 250, in clean
    self.user_cache = authenticate(
                      ~~~~~~~~~~~~^
        self.request, username=username, password=password
        ^^^^^^^^^^^^^^^^^^^^^^^^^^^^^^^^^^^^^^^^^^^^^^^^^^
    )
    ^
  File "C:\Users\SUBRAMANI\AppData\Roaming\Python\Python313\site-packages\django\views\decorators\debug.py", line 42, in sensitive_variables_wrapper
    return func(*func_args, **func_kwargs)
  File "C:\Users\SUBRAMANI\AppData\Roaming\Python\Python313\site-packages\django\contrib\auth\__init__.py", line 77, in authenticate
    user = backend.authenticate(request, **credentials)
  File "C:\Users\SUBRAMANI\AppData\Roaming\Python\Python313\site-packages\django\contrib\auth\backends.py", line 46, in authenticate
    user = UserModel._default_manager.get_by_natural_key(username)
  File "C:\Users\SUBRAMANI\AppData\Roaming\Python\Python313\site-packages\django\contrib\auth\base_user.py", line 54, in get_by_natural_key
    return self.get(**{self.model.USERNAME_FIELD: username})
           ~~~~~~~~^^^^^^^^^^^^^^^^^^^^^^^^^^^^^^^^^^^^^^^^^
  File "C:\Users\SUBRAMANI\AppData\Roaming\Python\Python313\site-packages\django\db\models\manager.py", line 87, in manager_method
    return getattr(self.get_queryset(), name)(*args, **kwargs)
           ~~~~~~~~~~~~~~~~~~~~~~~~~~~~~~~~~~^^^^^^^^^^^^^^^^^
  File "C:\Users\SUBRAMANI\AppData\Roaming\Python\Python313\site-packages\django\db\models\query.py", line 633, in get
    num = len(clone)
  File "C:\Users\SUBRAMANI\AppData\Roaming\Python\Python313\site-packages\django\db\models\query.py", line 380, in __len__
    self._fetch_all()
    ~~~~~~~~~~~~~~~^^
  File "C:\Users\SUBRAMANI\AppData\Roaming\Python\Python313\site-packages\django\db\models\query.py", line 1881, in _fetch_all
    self._result_cache = list(self._iterable_class(self))
                         ~~~~^^^^^^^^^^^^^^^^^^^^^^^^^^^^
  File "C:\Users\SUBRAMANI\AppData\Roaming\Python\Python313\site-packages\django\db\models\query.py", line 91, in __iter__
    results = compiler.execute_sql(
        chunked_fetch=self.chunked_fetch, chunk_size=self.chunk_size
    )
  File "C:\Users\SUBRAMANI\AppData\Roaming\Python\Python313\site-packages\django\db\models\sql\compiler.py", line 1562, in execute_sql
    cursor.execute(sql, params)
    ~~~~~~~~~~~~~~^^^^^^^^^^^^^
  File "C:\Users\SUBRAMANI\AppData\Roaming\Python\Python313\site-packages\django\db\backends\utils.py", line 102, in execute
    return super().execute(sql, params)
           ~~~~~~~~~~~~~~~^^^^^^^^^^^^^
  File "C:\Users\SUBRAMANI\AppData\Roaming\Python\Python313\site-packages\django\db\backends\utils.py", line 67, in execute
    return self._execute_with_wrappers(
           ~~~~~~~~~~~~~~~~~~~~~~~~~~~^
        sql, params, many=False, executor=self._execute
        ^^^^^^^^^^^^^^^^^^^^^^^^^^^^^^^^^^^^^^^^^^^^^^^
    )
    ^
  File "C:\Users\SUBRAMANI\AppData\Roaming\Python\Python313\site-packages\django\db\backends\utils.py", line 80, in _execute_with_wrappers
    return executor(sql, params, many, context)
  File "C:\Users\SUBRAMANI\AppData\Roaming\Python\Python313\site-packages\django\db\backends\utils.py", line 84, in _execute
    with self.db.wrap_database_errors:
         ^^^^^^^^^^^^^^^^^^^^^^^^^^^^
  File "C:\Users\SUBRAMANI\AppData\Roaming\Python\Python313\site-packages\django\db\utils.py", line 91, in __exit__
    raise dj_exc_value.with_traceback(traceback) from exc_value
  File "C:\Users\SUBRAMANI\AppData\Roaming\Python\Python313\site-packages\django\db\backends\utils.py", line 89, in _execute
    return self.cursor.execute(sql, params)
           ~~~~~~~~~~~~~~~~~~~^^^^^^^^^^^^^
  File "C:\Users\SUBRAMANI\AppData\Roaming\Python\Python313\site-packages\django\db\backends\sqlite3\base.py", line 328, in execute
    return super().execute(query, params)
           ~~~~~~~~~~~~~~~^^^^^^^^^^^^^^^
django.db.utils.OperationalError: no such table: auth_user
"POST /admin/login/?next=/admin/ HTTP/1.1" 500 247245
"GET /admin/login/?next=/admin/ HTTP/1.1" 200 4178
Internal Server Error: /admin/login/
Traceback (most recent call last):
  File "C:\Users\SUBRAMANI\AppData\Roaming\Python\Python313\site-packages\django\db\backends\utils.py", line 89, in _execute
    return self.cursor.execute(sql, params)
           ~~~~~~~~~~~~~~~~~~~^^^^^^^^^^^^^
  File "C:\Users\SUBRAMANI\AppData\Roaming\Python\Python313\site-packages\django\db\backends\sqlite3\base.py", line 328, in execute
    return super().execute(query, params)
           ~~~~~~~~~~~~~~~^^^^^^^^^^^^^^^
sqlite3.OperationalError: no such table: auth_user

The above exception was the direct cause of the following exception:

Traceback (most recent call last):
  File "C:\Users\SUBRAMANI\AppData\Roaming\Python\Python313\site-packages\django\core\handlers\exception.py", line 55, in inner
    response = get_response(request)
  File "C:\Users\SUBRAMANI\AppData\Roaming\Python\Python313\site-packages\django\core\handlers\base.py", line 197, in _get_response
    response = wrapped_callback(request, *callback_args, **callback_kwargs)
  File "C:\Users\SUBRAMANI\AppData\Roaming\Python\Python313\site-packages\django\utils\decorators.py", line 46, in _wrapper
    return bound_method(*args, **kwargs)
  File "C:\Users\SUBRAMANI\AppData\Roaming\Python\Python313\site-packages\django\views\decorators\cache.py", line 62, in _wrapper_view_func
    response = view_func(request, *args, **kwargs)
  File "C:\Users\SUBRAMANI\AppData\Roaming\Python\Python313\site-packages\django\contrib\admin\sites.py", line 441, in login
    return LoginView.as_view(**defaults)(request)
           ~~~~~~~~~~~~~~~~~~~~~~~~~~~~~^^^^^^^^^
  File "C:\Users\SUBRAMANI\AppData\Roaming\Python\Python313\site-packages\django\views\generic\base.py", line 104, in view
    return self.dispatch(request, *args, **kwargs)
           ~~~~~~~~~~~~~^^^^^^^^^^^^^^^^^^^^^^^^^^
  File "C:\Users\SUBRAMANI\AppData\Roaming\Python\Python313\site-packages\django\utils\decorators.py", line 46, in _wrapper
    return bound_method(*args, **kwargs)
  File "C:\Users\SUBRAMANI\AppData\Roaming\Python\Python313\site-packages\django\views\decorators\debug.py", line 92, in sensitive_post_parameters_wrapper
    return view(request, *args, **kwargs)
  File "C:\Users\SUBRAMANI\AppData\Roaming\Python\Python313\site-packages\django\utils\decorators.py", line 46, in _wrapper
    return bound_method(*args, **kwargs)
  File "C:\Users\SUBRAMANI\AppData\Roaming\Python\Python313\site-packages\django\utils\decorators.py", line 134, in _wrapper_view
    response = view_func(request, *args, **kwargs)
  File "C:\Users\SUBRAMANI\AppData\Roaming\Python\Python313\site-packages\django\utils\decorators.py", line 46, in _wrapper
    return bound_method(*args, **kwargs)
  File "C:\Users\SUBRAMANI\AppData\Roaming\Python\Python313\site-packages\django\views\decorators\cache.py", line 62, in _wrapper_view_func
    response = view_func(request, *args, **kwargs)
  File "C:\Users\SUBRAMANI\AppData\Roaming\Python\Python313\site-packages\django\contrib\auth\views.py", line 90, in dispatch
    return super().dispatch(request, *args, **kwargs)
           ~~~~~~~~~~~~~~~~^^^^^^^^^^^^^^^^^^^^^^^^^^
  File "C:\Users\SUBRAMANI\AppData\Roaming\Python\Python313\site-packages\django\views\generic\base.py", line 143, in dispatch
    return handler(request, *args, **kwargs)
  File "C:\Users\SUBRAMANI\AppData\Roaming\Python\Python313\site-packages\django\views\generic\edit.py", line 152, in post
    if form.is_valid():
       ~~~~~~~~~~~~~^^
  File "C:\Users\SUBRAMANI\AppData\Roaming\Python\Python313\site-packages\django\forms\forms.py", line 201, in is_valid
    return self.is_bound and not self.errors
                                 ^^^^^^^^^^^
  File "C:\Users\SUBRAMANI\AppData\Roaming\Python\Python313\site-packages\django\forms\forms.py", line 196, in errors
    self.full_clean()
    ~~~~~~~~~~~~~~~^^
  File "C:\Users\SUBRAMANI\AppData\Roaming\Python\Python313\site-packages\django\forms\forms.py", line 434, in full_clean
    self._clean_form()
    ~~~~~~~~~~~~~~~~^^
  File "C:\Users\SUBRAMANI\AppData\Roaming\Python\Python313\site-packages\django\forms\forms.py", line 455, in _clean_form
    cleaned_data = self.clean()
  File "C:\Users\SUBRAMANI\AppData\Roaming\Python\Python313\site-packages\django\contrib\auth\forms.py", line 250, in clean
    self.user_cache = authenticate(
                      ~~~~~~~~~~~~^
        self.request, username=username, password=password
        ^^^^^^^^^^^^^^^^^^^^^^^^^^^^^^^^^^^^^^^^^^^^^^^^^^
    )
    ^
  File "C:\Users\SUBRAMANI\AppData\Roaming\Python\Python313\site-packages\django\views\decorators\debug.py", line 42, in sensitive_variables_wrapper
    return func(*func_args, **func_kwargs)
  File "C:\Users\SUBRAMANI\AppData\Roaming\Python\Python313\site-packages\django\contrib\auth\__init__.py", line 77, in authenticate
    user = backend.authenticate(request, **credentials)
  File "C:\Users\SUBRAMANI\AppData\Roaming\Python\Python313\site-packages\django\contrib\auth\backends.py", line 46, in authenticate
    user = UserModel._default_manager.get_by_natural_key(username)
  File "C:\Users\SUBRAMANI\AppData\Roaming\Python\Python313\site-packages\django\contrib\auth\base_user.py", line 54, in get_by_natural_key
    return self.get(**{self.model.USERNAME_FIELD: username})
           ~~~~~~~~^^^^^^^^^^^^^^^^^^^^^^^^^^^^^^^^^^^^^^^^^
  File "C:\Users\SUBRAMANI\AppData\Roaming\Python\Python313\site-packages\django\db\models\manager.py", line 87, in manager_method
    return getattr(self.get_queryset(), name)(*args, **kwargs)
           ~~~~~~~~~~~~~~~~~~~~~~~~~~~~~~~~~~^^^^^^^^^^^^^^^^^
  File "C:\Users\SUBRAMANI\AppData\Roaming\Python\Python313\site-packages\django\db\models\query.py", line 633, in get
    num = len(clone)
  File "C:\Users\SUBRAMANI\AppData\Roaming\Python\Python313\site-packages\django\db\models\query.py", line 380, in __len__
    self._fetch_all()
    ~~~~~~~~~~~~~~~^^
  File "C:\Users\SUBRAMANI\AppData\Roaming\Python\Python313\site-packages\django\db\models\query.py", line 1881, in _fetch_all
    self._result_cache = list(self._iterable_class(self))
                         ~~~~^^^^^^^^^^^^^^^^^^^^^^^^^^^^
  File "C:\Users\SUBRAMANI\AppData\Roaming\Python\Python313\site-packages\django\db\models\query.py", line 91, in __iter__
    results = compiler.execute_sql(
        chunked_fetch=self.chunked_fetch, chunk_size=self.chunk_size
    )
  File "C:\Users\SUBRAMANI\AppData\Roaming\Python\Python313\site-packages\django\db\models\sql\compiler.py", line 1562, in execute_sql
    cursor.execute(sql, params)
    ~~~~~~~~~~~~~~^^^^^^^^^^^^^
  File "C:\Users\SUBRAMANI\AppData\Roaming\Python\Python313\site-packages\django\db\backends\utils.py", line 102, in execute
    return super().execute(sql, params)
           ~~~~~~~~~~~~~~~^^^^^^^^^^^^^
  File "C:\Users\SUBRAMANI\AppData\Roaming\Python\Python313\site-packages\django\db\backends\utils.py", line 67, in execute
    return self._execute_with_wrappers(
           ~~~~~~~~~~~~~~~~~~~~~~~~~~~^
        sql, params, many=False, executor=self._execute
        ^^^^^^^^^^^^^^^^^^^^^^^^^^^^^^^^^^^^^^^^^^^^^^^
    )
    ^
  File "C:\Users\SUBRAMANI\AppData\Roaming\Python\Python313\site-packages\django\db\backends\utils.py", line 80, in _execute_with_wrappers
    return executor(sql, params, many, context)
  File "C:\Users\SUBRAMANI\AppData\Roaming\Python\Python313\site-packages\django\db\backends\utils.py", line 84, in _execute
    with self.db.wrap_database_errors:
         ^^^^^^^^^^^^^^^^^^^^^^^^^^^^
  File "C:\Users\SUBRAMANI\AppData\Roaming\Python\Python313\site-packages\django\db\utils.py", line 91, in __exit__
    raise dj_exc_value.with_traceback(traceback) from exc_value
  File "C:\Users\SUBRAMANI\AppData\Roaming\Python\Python313\site-packages\django\db\backends\utils.py", line 89, in _execute
    return self.cursor.execute(sql, params)
           ~~~~~~~~~~~~~~~~~~~^^^^^^^^^^^^^
  File "C:\Users\SUBRAMANI\AppData\Roaming\Python\Python313\site-packages\django\db\backends\sqlite3\base.py", line 328, in execute
    return super().execute(query, params)
           ~~~~~~~~~~~~~~~^^^^^^^^^^^^^^^
django.db.utils.OperationalError: no such table: auth_user
"POST /admin/login/?next=/admin/ HTTP/1.1" 500 247245
"GET /admin/login/?next=/admin/ HTTP/1.1" 200 4178
Watching for file changes with StatReloader
Not Found: /
"GET / HTTP/1.1" 404 2773
"GET /admin/login/?next=/admin/ HTTP/1.1" 200 4178
Watching for file changes with StatReloader
"GET /admin/login/?next=/admin/ HTTP/1.1" 200 4178
"POST /admin/login/?next=/admin/ HTTP/1.1" 302 0
"GET /admin/ HTTP/1.1" 200 17332
"GET /static/admin/css/dashboard.css HTTP/1.1" 200 441
"GET /static/admin/img/icon-addlink.svg HTTP/1.1" 200 331
"GET /static/admin/img/icon-changelink.svg HTTP/1.1" 200 380
"GET /admin/authentication/userprofile/ HTTP/1.1" 200 17087
"GET /static/admin/css/changelists.css HTTP/1.1" 200 6566
"GET /static/admin/js/core.js HTTP/1.1" 200 5682
"GET /static/admin/js/jquery.init.js HTTP/1.1" 200 347
"GET /static/admin/js/actions.js HTTP/1.1" 200 7872
"GET /static/admin/js/admin/RelatedObjectLookups.js HTTP/1.1" 200 8943
"GET /static/admin/js/urlify.js HTTP/1.1" 200 7887
"GET /static/admin/js/prepopulate.js HTTP/1.1" 200 1531
"GET /admin/jsi18n/ HTTP/1.1" 200 3343
"GET /static/admin/js/vendor/jquery/jquery.js HTTP/1.1" 200 292458
"GET /static/admin/img/search.svg HTTP/1.1" 200 458
"GET /static/admin/js/vendor/xregexp/xregexp.js HTTP/1.1" 200 232381
"GET /static/admin/js/filters.js HTTP/1.1" 200 978
"GET /static/admin/img/tooltag-add.svg HTTP/1.1" 200 331
"GET /admin/authentication/user/ HTTP/1.1" 200 21061
"GET /static/admin/img/icon-yes.svg HTTP/1.1" 200 436
"GET /static/admin/img/icon-no.svg HTTP/1.1" 200 560
"GET /admin/jsi18n/ HTTP/1.1" 200 3343
"GET /static/admin/img/sorting-icons.svg HTTP/1.1" 200 1097
"GET /admin/authentication/user/add/ HTTP/1.1" 200 21816
"GET /static/admin/js/prepopulate_init.js HTTP/1.1" 200 586
"GET /static/admin/css/forms.css HTTP/1.1" 200 9047
"GET /admin/jsi18n/ HTTP/1.1" 200 3343
"GET /static/admin/js/change_form.js HTTP/1.1" 200 606
"GET /static/admin/css/widgets.css HTTP/1.1" 200 11900
"POST /admin/authentication/user/add/ HTTP/1.1" 302 0
"GET /admin/authentication/user/2/change/ HTTP/1.1" 200 38637
"GET /static/admin/js/SelectBox.js HTTP/1.1" 200 4530
"GET /static/admin/js/SelectFilter2.js HTTP/1.1" 200 15292
"GET /static/admin/js/calendar.js HTTP/1.1" 200 8466
"GET /static/admin/js/admin/DateTimeShortcuts.js HTTP/1.1" 200 19319
"GET /admin/jsi18n/ HTTP/1.1" 200 3343
"GET /static/admin/img/icon-unknown.svg HTTP/1.1" 200 655
"GET /static/admin/img/selector-icons.svg HTTP/1.1" 200 3291
"GET /static/admin/img/icon-calendar.svg HTTP/1.1" 200 1086
"GET /static/admin/img/icon-unknown-alt.svg HTTP/1.1" 200 655
"GET /static/admin/img/icon-clock.svg HTTP/1.1" 200 677
"GET /admin/authentication/user/ HTTP/1.1" 200 21670
"GET /admin/jsi18n/ HTTP/1.1" 200 3343
Watching for file changes with StatReloader
Watching for file changes with StatReloader
Watching for file changes with StatReloader
"POST /api/auth/login/ HTTP/1.1" 200 621
"POST /api/auth/register/ HTTP/1.1" 201 714
"OPTIONS /api/auth/login/ HTTP/1.1" 200 0
"POST /api/auth/login/ HTTP/1.1" 200 621
"OPTIONS /api/auth/register/ HTTP/1.1" 200 0
Bad Request: /api/auth/register/
"POST /api/auth/register/ HTTP/1.1" 400 83
Bad Request: /api/auth/register/
"POST /api/auth/register/ HTTP/1.1" 400 83
"POST /api/auth/register/ HTTP/1.1" 201 724
C:\Users\SUBRAMANI\dine\Ecoshift\backend\merchants\views.py changed, reloading.
Watching for file changes with StatReloader
C:\Users\SUBRAMANI\dine\Ecoshift\backend\merchants\views.py changed, reloading.
Watching for file changes with StatReloader
C:\Users\SUBRAMANI\dine\Ecoshift\backend\merchants\views.py changed, reloading.
Watching for file changes with StatReloader
C:\Users\SUBRAMANI\dine\Ecoshift\backend\merchants\views.py changed, reloading.
Watching for file changes with StatReloader
C:\Users\SUBRAMANI\dine\Ecoshift\backend\merchants\urls.py changed, reloading.
Watching for file changes with StatReloader
"OPTIONS /api/merchants/products/ HTTP/1.1" 200 0
Not Found: /api/merchants/products/
"GET /api/merchants/products/ HTTP/1.1" 404 23
"OPTIONS /api/merchants/orders/ HTTP/1.1" 200 0
Not Found: /api/merchants/orders/
"GET /api/merchants/orders/ HTTP/1.1" 404 23
"OPTIONS /api/merchants/dashboard/ HTTP/1.1" 200 0
Not Found: /api/merchants/dashboard/
"GET /api/merchants/dashboard/ HTTP/1.1" 404 38
"POST /api/auth/login/ HTTP/1.1" 200 638
Unauthorized: /api/merchants/dashboard/
"GET /api/merchants/dashboard/ HTTP/1.1" 401 183
"POST /api/auth/login/ HTTP/1.1" 200 638
"GET /api/merchants/dashboard/ HTTP/1.1" 200 4073
"POST /api/auth/login/ HTTP/1.1" 200 638
"GET /api/merchants/products/ HTTP/1.1" 200 3925
"POST /api/auth/login/ HTTP/1.1" 200 638
"GET /api/merchants/orders/ HTTP/1.1" 200 10347
C:\Users\SUBRAMANI\dine\Ecoshift\backend\merchants\views.py changed, reloading.
Watching for file changes with StatReloader
Not Found: /api/merchants/products/
"GET /api/merchants/products/ HTTP/1.1" 404 23
Not Found: /api/merchants/products/
"GET /api/merchants/products/ HTTP/1.1" 404 23
Not Found: /api/merchants/orders/
"GET /api/merchants/orders/ HTTP/1.1" 404 23
Not Found: /api/merchants/orders/
"GET /api/merchants/orders/ HTTP/1.1" 404 23
Not Found: /api/merchants/dashboard/
"GET /api/merchants/dashboard/ HTTP/1.1" 404 38
Not Found: /api/merchants/dashboard/
"GET /api/merchants/dashboard/ HTTP/1.1" 404 38
Not Found: /api/merchants/products/
"GET /api/merchants/products/ HTTP/1.1" 404 23
Not Found: /api/merchants/products/
"GET /api/merchants/products/ HTTP/1.1" 404 23
Not Found: /api/merchants/orders/
"GET /api/merchants/orders/ HTTP/1.1" 404 23
Not Found: /api/merchants/orders/
"GET /api/merchants/orders/ HTTP/1.1" 404 23
Not Found: /api/merchants/dashboard/
"GET /api/merchants/dashboard/ HTTP/1.1" 404 38
Not Found: /api/merchants/dashboard/
"GET /api/merchants/dashboard/ HTTP/1.1" 404 38
"POST /api/auth/login/ HTTP/1.1" 200 638
"GET /api/merchants/products/ HTTP/1.1" 200 3925
"GET /api/merchants/products/ HTTP/1.1" 200 3925
"GET /api/merchants/orders/ HTTP/1.1" 200 10347
"GET /api/merchants/orders/ HTTP/1.1" 200 10347
"GET /api/merchants/dashboard/ HTTP/1.1" 200 4073
"GET /api/merchants/dashboard/ HTTP/1.1" 200 4073
"OPTIONS /api/merchants/products/?search=Organic+Cotton+Tote+Bag HTTP/1.1" 200 0
"GET /api/merchants/products/?search=Organic+Cotton+Tote+Bag HTTP/1.1" 200 831
"OPTIONS /api/merchants/products/? HTTP/1.1" 200 0
"GET /api/merchants/products/? HTTP/1.1" 200 3925
"OPTIONS /api/merchants/products/4/ HTTP/1.1" 200 0
"DELETE /api/merchants/products/4/ HTTP/1.1" 204 0
"GET /api/merchants/products/ HTTP/1.1" 200 3158
"GET /api/merchants/orders/ HTTP/1.1" 200 10089
"GET /api/merchants/dashboard/ HTTP/1.1" 200 3760
"OPTIONS /api/merchants/products/3/update_stock/ HTTP/1.1" 200 0
Unsupported Media Type: /api/merchants/products/3/update_stock/
"POST /api/merchants/products/3/update_stock/ HTTP/1.1" 415 68
Unsupported Media Type: /api/merchants/products/3/update_stock/
"POST /api/merchants/products/3/update_stock/ HTTP/1.1" 415 68
"OPTIONS /api/merchants/orders/15/update_status/ HTTP/1.1" 200 0
"POST /api/merchants/orders/15/update_status/ HTTP/1.1" 200 66
"GET /api/merchants/products/ HTTP/1.1" 200 3158
"GET /api/merchants/orders/ HTTP/1.1" 200 10087
"GET /api/merchants/dashboard/ HTTP/1.1" 200 3758
"POST /api/merchants/orders/15/update_status/ HTTP/1.1" 200 68
"GET /api/merchants/products/ HTTP/1.1" 200 3158
"GET /api/merchants/orders/ HTTP/1.1" 200 10089
"GET /api/merchants/dashboard/ HTTP/1.1" 200 3760
"GET /api/merchants/products/ HTTP/1.1" 200 3158
"GET /api/merchants/products/ HTTP/1.1" 200 3158
"GET /api/merchants/orders/ HTTP/1.1" 200 10089
"GET /api/merchants/orders/ HTTP/1.1" 200 10089
"GET /api/merchants/dashboard/ HTTP/1.1" 200 3760
"GET /api/merchants/dashboard/ HTTP/1.1" 200 3760
"GET /api/merchants/products/ HTTP/1.1" 200 3158
"GET /api/merchants/products/ HTTP/1.1" 200 3158
"GET /api/merchants/orders/ HTTP/1.1" 200 10089
"GET /api/merchants/dashboard/ HTTP/1.1" 200 3760
"GET /api/merchants/orders/ HTTP/1.1" 200 10089
"GET /api/merchants/dashboard/ HTTP/1.1" 200 3760
"GET /api/merchants/products/ HTTP/1.1" 200 3158
"GET /api/merchants/products/ HTTP/1.1" 200 3158
"GET /api/merchants/orders/ HTTP/1.1" 200 10089
"GET /api/merchants/dashboard/ HTTP/1.1" 200 3760
"GET /api/merchants/orders/ HTTP/1.1" 200 10089
"GET /api/merchants/dashboard/ HTTP/1.1" 200 3760
"OPTIONS /api/merchants/products/?search=Reusable+Water+Bottle&category=Personal+Care HTTP/1.1" 200 0
"GET /api/merchants/products/?search=Reusable+Water+Bottle&category=Personal+Care HTTP/1.1" 200 52
"GET /api/merchants/products/? HTTP/1.1" 200 3158
"POST /api/merchants/orders/15/update_status/ HTTP/1.1" 200 69
"GET /api/merchants/products/ HTTP/1.1" 200 3158
"GET /api/merchants/orders/ HTTP/1.1" 200 10090
"GET /api/merchants/dashboard/ HTTP/1.1" 200 3761
"POST /api/merchants/orders/15/update_status/ HTTP/1.1" 200 66
"GET /api/merchants/products/ HTTP/1.1" 200 3158
"GET /api/merchants/orders/ HTTP/1.1" 200 10087
"GET /api/merchants/dashboard/ HTTP/1.1" 200 3758
"POST /api/merchants/orders/15/update_status/ HTTP/1.1" 200 68
"GET /api/merchants/products/ HTTP/1.1" 200 3158
"GET /api/merchants/orders/ HTTP/1.1" 200 10089
"GET /api/merchants/dashboard/ HTTP/1.1" 200 3760
"POST /api/auth/login/ HTTP/1.1" 200 621
C:\Users\SUBRAMANI\dine\Ecoshift\backend\customers\views.py changed, reloading.
Watching for file changes with StatReloader
C:\Users\SUBRAMANI\dine\Ecoshift\backend\customers\views.py changed, reloading.
Watching for file changes with StatReloader
C:\Users\SUBRAMANI\dine\Ecoshift\backend\customers\views.py changed, reloading.
Watching for file changes with StatReloader
C:\Users\SUBRAMANI\dine\Ecoshift\backend\customers\views.py changed, reloading.
Watching for file changes with StatReloader
C:\Users\SUBRAMANI\dine\Ecoshift\backend\customers\views.py changed, reloading.
Watching for file changes with StatReloader
C:\Users\SUBRAMANI\dine\Ecoshift\backend\customers\urls.py changed, reloading.
Watching for file changes with StatReloader
C:\Users\SUBRAMANI\dine\Ecoshift\backend\customers\urls.py changed, reloading.
Watching for file changes with StatReloader
Forbidden (CSRF token from POST incorrect.): /admin/login/
"POST /admin/login/?next=/admin/ HTTP/1.1" 403 2518
Forbidden (CSRF token from POST incorrect.): /admin/login/
"POST /admin/login/?next=/admin/ HTTP/1.1" 403 2518
"GET /admin/authentication/user/ HTTP/1.1" 200 24164
"GET /static/admin/css/base.css HTTP/1.1" 304 0
"GET /static/admin/css/dark_mode.css HTTP/1.1" 304 0
"GET /static/admin/css/nav_sidebar.css HTTP/1.1" 304 0
"GET /static/admin/css/responsive.css HTTP/1.1" 304 0
"GET /admin/jsi18n/ HTTP/1.1" 200 3343
"GET /static/admin/js/theme.js HTTP/1.1" 304 0
"GET /static/admin/js/nav_sidebar.js HTTP/1.1" 304 0
"GET /admin/authentication/user/6/change/ HTTP/1.1" 200 38403
"GET /admin/jsi18n/ HTTP/1.1" 200 3343
"GET /admin/authentication/user/6/password/ HTTP/1.1" 200 15771
"POST /admin/authentication/user/6/password/ HTTP/1.1" 302 0
"GET /admin/authentication/user/6/change/ HTTP/1.1" 200 38539
"GET /admin/jsi18n/ HTTP/1.1" 200 3343
"POST /api/auth/login/ HTTP/1.1" 200 638
"POST /api/auth/login/ HTTP/1.1" 200 640
Not Found: /api/merchants/products/
"GET /api/merchants/products/ HTTP/1.1" 404 23
Not Found: /api/merchants/products/
"GET /api/merchants/products/ HTTP/1.1" 404 23
Not Found: /api/merchants/products/
"GET /api/merchants/products/ HTTP/1.1" 404 23
Not Found: /api/merchants/products/
"GET /api/merchants/products/ HTTP/1.1" 404 23
Not Found: /api/merchants/orders/
"GET /api/merchants/orders/ HTTP/1.1" 404 23
Not Found: /api/merchants/orders/
"GET /api/merchants/orders/ HTTP/1.1" 404 23
Not Found: /api/merchants/dashboard/
"GET /api/merchants/dashboard/ HTTP/1.1" 404 38
Not Found: /api/merchants/dashboard/
"GET /api/merchants/dashboard/ HTTP/1.1" 404 38
"GET /admin/authentication/user/6/password/ HTTP/1.1" 200 15771
"GET /admin/authentication/user/6/change/ HTTP/1.1" 200 38403
"GET /admin/authentication/user/ HTTP/1.1" 200 24164
"GET /admin/authentication/user/5/change/ HTTP/1.1" 200 38403
"GET /admin/jsi18n/ HTTP/1.1" 200 3343
"GET /admin/authentication/user/5/password/ HTTP/1.1" 200 15771
"POST /admin/authentication/user/5/password/ HTTP/1.1" 302 0
"GET /admin/authentication/user/5/change/ HTTP/1.1" 200 38539
"GET /admin/jsi18n/ HTTP/1.1" 200 3343
"POST /api/auth/login/ HTTP/1.1" 200 638
"GET /api/merchants/products/ HTTP/1.1" 200 3158
"GET /api/merchants/products/ HTTP/1.1" 200 3158
"GET /api/merchants/products/ HTTP/1.1" 200 3158
"GET /api/merchants/products/ HTTP/1.1" 200 3158
"GET /api/merchants/orders/ HTTP/1.1" 200 10089
"GET /api/merchants/dashboard/ HTTP/1.1" 200 3760
"GET /api/merchants/orders/ HTTP/1.1" 200 10089
"GET /api/merchants/dashboard/ HTTP/1.1" 200 3760
"OPTIONS /api/merchants/analytics/sales/?days=30 HTTP/1.1" 200 0
"OPTIONS /api/merchants/analytics/sales/?days=30 HTTP/1.1" 200 0
Not Found: /api/merchants/analytics/sales/
"GET /api/merchants/analytics/sales/?days=30 HTTP/1.1" 404 23
Not Found: /api/merchants/analytics/sales/
"GET /api/merchants/analytics/sales/?days=30 HTTP/1.1" 404 23
Unsupported Media Type: /api/merchants/products/
"POST /api/merchants/products/ HTTP/1.1" 415 68
Unsupported Media Type: /api/merchants/products/
"POST /api/merchants/products/ HTTP/1.1" 415 68
Unsupported Media Type: /api/merchants/products/
"POST /api/merchants/products/ HTTP/1.1" 415 68
Unsupported Media Type: /api/merchants/products/
"POST /api/merchants/products/ HTTP/1.1" 415 68
Watching for file changes with StatReloader
Unsupported Media Type: /api/merchants/products/
"POST /api/merchants/products/ HTTP/1.1" 415 68
"GET /api/merchants/products/ HTTP/1.1" 200 3158
"GET /api/merchants/products/ HTTP/1.1" 200 3158
"GET /api/merchants/orders/ HTTP/1.1" 200 10089
"GET /api/merchants/orders/ HTTP/1.1" 200 10089
"GET /api/merchants/dashboard/ HTTP/1.1" 200 3760
"GET /api/merchants/dashboard/ HTTP/1.1" 200 3760
"POST /api/auth/login/ HTTP/1.1" 200 638
"GET /api/merchants/products/ HTTP/1.1" 200 3158
"GET /api/merchants/products/ HTTP/1.1" 200 3158
"GET /api/merchants/products/ HTTP/1.1" 200 3158
"GET /api/merchants/products/ HTTP/1.1" 200 3158
"GET /api/merchants/orders/ HTTP/1.1" 200 10089
"GET /api/merchants/dashboard/ HTTP/1.1" 200 3760
"GET /api/merchants/orders/ HTTP/1.1" 200 10089
"GET /api/merchants/dashboard/ HTTP/1.1" 200 3760
Unsupported Media Type: /api/merchants/products/
"POST /api/merchants/products/ HTTP/1.1" 415 68
Not Found: /
"GET / HTTP/1.1" 404 2773
Not Found: /favicon.ico
"GET /favicon.ico HTTP/1.1" 404 2824
Not Found: /
"GET / HTTP/1.1" 404 2773
Watching for file changes with StatReloader
Watching for file changes with StatReloader
Not Found: /
"GET / HTTP/1.1" 404 2773
Watching for file changes with StatReloader
Not Found: /
"GET / HTTP/1.1" 404 2773
C:\Users\SUBRAMANI\dine\Ecoshift\backend\ecoswitch_backend\settings.py changed, reloading.
